Workbook

Sheet Wheat_Yield_Data
A1: District | B1: Season | C1: Wheat Area (ha) | D1: Wheat Production (tonnes) | E1: Wheat Yield (kg/ha) | F1: Source | G1: Source URL | H1: Verification Status
A2: Attock | B2: 2010-11 | C2: 155800 | D2: 252650 | E2: 1621 | F2: CRS Punjab - Rabi Crops Estimates 2011-12 (prior-year column) | G2: https://agripunjab.punjab.gov.pk/system/files/Rabi%20Book%20All%20estimates%202011-12_0.pdf | H2: Verified: directly reported (CRS prior-year column of the following season report)
A3: Attock | B3: 2011-12 | C3: 155390 | D3: 167110 | E3: 1075 | F3: CRS Punjab - Rabi Crops Estimates 2011-12 | G3: https://agripunjab.punjab.gov.pk/system/files/Rabi%20Book%20All%20estimates%202011-12_0.pdf | H3: Verified: directly reported (CRS final estimate)
A4: Attock | B4: 2012-13 | C4: 155800 | D4: 164470 | E4: 1056 | F4: CRS Punjab - Rabi Crop Estimates Data Book 2013-14 (prior-year column) | G4: https://agripunjab.punjab.gov.pk/system/files/Final%20Rabi%20Estimates%202013-14.pdf | H4: Verified: directly reported (CRS prior-year column of the following season report)
A5: Attock | B5: 2013-14 | C5: 159040 | D5: 218330 | E5: 1372 | F5: CRS Punjab - Rabi Crop Estimates Data Book 2013-14 | G5: https://agripunjab.punjab.gov.pk/system/files/Final%20Rabi%20Estimates%202013-14.pdf | H5: Verified: directly reported (CRS final estimate)
A6: Attock | B6: 2014-15 | C6: 173610 | D6: 300940 | E6: 1733 | F6: CRS Punjab - Rabi Book 2015-16 (prior-year column) | G6: https://agripunjab.punjab.gov.pk/system/files/RABI%20BOOK%202015-16_0.pdf | H6: Verified: directly reported (CRS prior-year column of the following season report)
A7: Attock | B7: 2015-16 | C7: 187770 | D7: 335230 | E7: =D7*1000/C7 -> 1785.3225 | F7: CRS Punjab - Rabi Book 2015-16 | G7: https://agripunjab.punjab.gov.pk/system/files/RABI%20BOOK%202015-16_0.pdf | H7: Verified: yield calculated from official area & production (printed total yield differs, see notes)
A8: Attock | B8: 2016-17 | C8: 151350 | D8: 205030 | E8: 1355 | F8: CRS Punjab - Final Rabi Estimates 2017-18 (prior-year column) | G8: https://agripunjab.punjab.gov.pk/system/files/Final%20%20Rabi%20Estimates%202017-18.pdf | H8: Verified: directly reported (CRS prior-year column of the following season report)
A9: Attock | B9: 2017-18 | C9: 151350 | D9: 223130 | E9: 1474 | F9: CRS Punjab - Final Rabi Estimates 2017-18 | G9: https://agripunjab.punjab.gov.pk/system/files/Final%20%20Rabi%20Estimates%202017-18.pdf | H9: Verified: directly reported (CRS final estimate)
A10: Attock | B10: 2018-19 | C10: 151350 | D10: 286930 | E10: 1895 | F10: CRS Punjab - Final Rabi Estimates 2018-19 | G10: https://agripunjab.punjab.gov.pk/system/files/Final%20Rabi%20Estimates%202018-19.pdf | H10: Verified: directly reported (CRS final estimate)
A11: Attock | B11: 2020-21 | C11: 203150 | D11: 359000 | E11: 1767 | F11: CRS Punjab - Rabi Crops Estimates 2021-22 (prior-year column) | G11: https://agripunjab.punjab.gov.pk/system/files/Final%20Rabi%20Estimates%202021-22.pdf | H11: Verified: directly reported (CRS prior-year column of the following season report); printed area total corrected from printed components (see notes)
A12: Attock | B12: 2021-22 | C12: 182920 | D12: 310340 | E12: 1697 | F12: CRS Punjab - Rabi Crops Estimates 2021-22 | G12: https://agripunjab.punjab.gov.pk/system/files/Final%20Rabi%20Estimates%202021-22.pdf | H12: Verified: directly reported (CRS final estimate)
A13: Attock | B13: 2022-23 | C13: 190200 | D13: 348200 | E13: 1831 | F13: CRS Punjab - Final Rabi Estimates 2022-23 | G13: https://agripunjab.punjab.gov.pk/system/files/Final%20Rabi%20Estimates%202022-23.pdf | H13: Verified: directly reported (CRS final estimate)
A14: Bahawalnagar | B14: 2010-11 | C14: 344780 | D14: 1076710 | E14: 3123 | F14: CRS Punjab - Rabi Crops Estimates 2011-12 (prior-year column) | G14: https://agripunjab.punjab.gov.pk/system/files/Rabi%20Book%20All%20estimates%202011-12_0.pdf | H14: Verified: directly reported (CRS prior-year column of the following season report)
A15: Bahawalnagar | B15: 2011-12 | C15: 336290 | D15: 989160 | E15: 2941 | F15: CRS Punjab - Rabi Crops Estimates 2011-12 | G15: https://agripunjab.punjab.gov.pk/system/files/Rabi%20Book%20All%20estimates%202011-12_0.pdf | H15: Verified: directly reported (CRS final estimate)
A16: Bahawalnagar | B16: 2012-13 | C16: 335890 | D16: 1002070 | E16: 2984 | F16: CRS Punjab - Rabi Crop Estimates Data Book 2013-14 (prior-year column) | G16: https://agripunjab.punjab.gov.pk/system/files/Final%20Rabi%20Estimates%202013-14.pdf | H16: Verified: directly reported (CRS prior-year column of the following season report)
A17: Bahawalnagar | B17: 2013-14 | C17: 358950 | D17: 1089550 | E17: 3035 | F17: CRS Punjab - Rabi Crop Estimates Data Book 2013-14 | G17: https://agripunjab.punjab.gov.pk/system/files/Final%20Rabi%20Estimates%202013-14.pdf | H17: Verified: directly reported (CRS final estimate)
A18: Bahawalnagar | B18: 2014-15 | C18: 369060 | D18: 1161200 | E18: 3146 | F18: CRS Punjab - Rabi Book 2015-16 (prior-year column) | G18: https://agripunjab.punjab.gov.pk/system/files/RABI%20BOOK%202015-16_0.pdf | H18: Verified: directly reported (CRS prior-year column of the following season report)
A19: Bahawalnagar | B19: 2015-16 | C19: 371090 | D19: 1132480 | E19: =D19*1000/C19 -> 3051.7664 | F19: CRS Punjab - Rabi Book 2015-16 | G19: https://agripunjab.punjab.gov.pk/system/files/RABI%20BOOK%202015-16_0.pdf | H19: Verified: yield calculated from official area & production (printed total yield differs, see notes)
A20: Bahawalnagar | B20: 2016-17 | C20: 372710 | D20: 1218430 | E20: 3269 | F20: CRS Punjab - Final Rabi Estimates 2017-18 (prior-year column) | G20: https://agripunjab.punjab.gov.pk/system/files/Final%20%20Rabi%20Estimates%202017-18.pdf | H20: Verified: directly reported (CRS prior-year column of the following season report)
A21: Bahawalnagar | B21: 2017-18 | C21: 369070 | D21: 1132710 | E21: 3069 | F21: CRS Punjab - Final Rabi Estimates 2017-18 | G21: https://agripunjab.punjab.gov.pk/system/files/Final%20%20Rabi%20Estimates%202017-18.pdf | H21: Verified: directly reported (CRS final estimate)
A22: Bahawalnagar | B22: 2018-19 | C22: 356920 | D22: 1158390 | E22: 3246 | F22: CRS Punjab - Final Rabi Estimates 2018-19 | G22: https://agripunjab.punjab.gov.pk/system/files/Final%20Rabi%20Estimates%202018-19.pdf | H22: Verified: directly reported (CRS final estimate)
A23: Bahawalnagar | B23: 2020-21 | C23: 426930 | D23: 1587150 | E23: 3718 | F23: CRS Punjab - Rabi Crops Estimates 2021-22 (prior-year column) | G23: https://agripunjab.punjab.gov.pk/system/files/Final%20Rabi%20Estimates%202021-22.pdf | H23: Verified: directly reported (CRS prior-year column of the following season report)
A24: Bahawalnagar | B24: 2021-22 | C24: 424910 | D24: 1513890 | E24: 3562 | F24: CRS Punjab - Rabi Crops Estimates 2021-22 | G24: https://agripunjab.punjab.gov.pk/system/files/Final%20Rabi%20Estimates%202021-22.pdf | H24: Verified: directly reported (CRS final estimate)
A25: Bahawalnagar | B25: 2022-23 | C25: 423300 | D25: 1563000 | E25: 3693 | F25: CRS Punjab - Final Rabi Estimates 2022-23 | G25: https://agripunjab.punjab.gov.pk/system/files/Final%20Rabi%20Estimates%202022-23.pdf | H25: Verified: directly reported (CRS final estimate)
A26: Bahawalpur | B26: 2010-11 | C26: 280440 | D26: 881900 | E26: 3145 | F26: CRS Punjab - Rabi Crops Estimates 2011-12 (prior-year column) | G26: https://agripunjab.punjab.gov.pk/system/files/Rabi%20Book%20All%20estimates%202011-12_0.pdf | H26: Verified: directly reported (CRS prior-year column of the following season report)
A27: Bahawalpur | B27: 2011-12 | C27: 262230 | D27: 836770 | E27: 3191 | F27: CRS Punjab - Rabi Crops Estimates 2011-12 | G27: https://agripunjab.punjab.gov.pk/system/files/Rabi%20Book%20All%20estimates%202011-12_0.pdf | H27: Verified: directly reported (CRS final estimate)
A28: Bahawalpur | B28: 2012-13 | C28: 265460 | D28: 796160 | E28: 2999 | F28: CRS Punjab - Rabi Crop Estimates Data Book 2013-14 (prior-year column) | G28: https://agripunjab.punjab.gov.pk/system/files/Final%20Rabi%20Estimates%202013-14.pdf | H28: Verified: directly reported (CRS prior-year column of the following season report)
A29: Bahawalpur | B29: 2013-14 | C29: 291370 | D29: 881300 | E29: 3024 | F29: CRS Punjab - Rabi Crop Estimates Data Book 2013-14 | G29: https://agripunjab.punjab.gov.pk/system/files/Final%20Rabi%20Estimates%202013-14.pdf | H29: Verified: directly reported (CRS final estimate)
A30: Bahawalpur | B30: 2014-15 | C30: 297040 | D30: 905110 | E30: 3047 | F30: CRS Punjab - Rabi Book 2015-16 (prior-year column) | G30: https://agripunjab.punjab.gov.pk/system/files/RABI%20BOOK%202015-16_0.pdf | H30: Verified: directly reported (CRS prior-year column of the following season report)
A31: Bahawalpur | B31: 2015-16 | C31: 300270 | D31: 969030 | E31: =D31*1000/C31 -> 3227.1955 | F31: CRS Punjab - Rabi Book 2015-16 | G31: https://agripunjab.punjab.gov.pk/system/files/RABI%20BOOK%202015-16_0.pdf | H31: Verified: yield calculated from official area & production (printed total yield differs, see notes)
A32: Bahawalpur | B32: 2016-17 | C32: 289350 | D32: 984490 | E32: 3402 | F32: CRS Punjab - Final Rabi Estimates 2017-18 (prior-year column) | G32: https://agripunjab.punjab.gov.pk/system/files/Final%20%20Rabi%20Estimates%202017-18.pdf | H32: Verified: directly reported (CRS prior-year column of the following season report)
A33: Bahawalpur | B33: 2017-18 | C33: 286110 | D33: 921880 | E33: 3222 | F33: CRS Punjab - Final Rabi Estimates 2017-18 | G33: https://agripunjab.punjab.gov.pk/system/files/Final%20%20Rabi%20Estimates%202017-18.pdf | H33: Verified: directly reported (CRS final estimate)
A34: Bahawalpur | B34: 2018-19 | C34: 285300 | D34: 860460 | E34: 3016 | F34: CRS Punjab - Final Rabi Estimates 2018-19 | G34: https://agripunjab.punjab.gov.pk/system/files/Final%20Rabi%20Estimates%202018-19.pdf | H34: Verified: directly reported (CRS final estimate)
A35: Bahawalpur | B35: 2020-21 | C35: 301080 | D35: 1002910 | E35: 3331 | F35: CRS Punjab - Rabi Crops Estimates 2021-22 (prior-year column) | G35: https://agripunjab.punjab.gov.pk/system/files/Final%20Rabi%20Estimates%202021-22.pdf | H35: Verified: directly reported (CRS prior-year column of the following season report)
A36: Bahawalpur | B36: 2021-22 | C36: 295820 | D36: 1052060 | E36: 3556 | F36: CRS Punjab - Rabi Crops Estimates 2021-22 | G36: https://agripunjab.punjab.gov.pk/system/files/Final%20Rabi%20Estimates%202021-22.pdf | H36: Verified: directly reported (CRS final estimate)
A37: Bahawalpur | B37: 2022-23 | C37: 287700 | D37: 1073600 | E37: 3731 | F37: CRS Punjab - Final Rabi Estimates 2022-23 | G37: https://agripunjab.punjab.gov.pk/system/files/Final%20Rabi%20Estimates%202022-23.pdf | H37: Verified: directly reported (CRS final estimate)
A38: Bhakkar | B38: 2010-11 | C38: 181700 | D38: 444420 | E38: 2446 | F38: CRS Punjab - Rabi Crops Estimates 2011-12 (prior-year column) | G38: https://agripunjab.punjab.gov.pk/system/files/Rabi%20Book%20All%20estimates%202011-12_0.pdf | H38: Verified: directly reported (CRS prior-year column of the following season report)
A39: Bhakkar | B39: 2011-12 | C39: 173610 | D39: 387760 | E39: 2234 | F39: CRS Punjab - Rabi Crops Estimates 2011-12 | G39: https://agripunjab.punjab.gov.pk/system/files/Rabi%20Book%20All%20estimates%202011-12_0.pdf | H39: Verified: directly reported (CRS final estimate)
A40: Bhakkar | B40: 2012-13 | C40: 167940 | D40: 409350 | E40: 2438 | F40: CRS Punjab - Rabi Crop Estimates Data Book 2013-14 (prior-year column) | G40: https://agripunjab.punjab.gov.pk/system/files/Final%20Rabi%20Estimates%202013-14.pdf | H40: Verified: directly reported (CRS prior-year column of the following season report)
...

Sheet Source_Verification
A1: District | B1: Season | C1: Area (ha) | D1: Production (tonnes) | E1: Yield (kg/ha) | F1: Source Document | G1: Source URL | H1: Page/Table Number | I1: Directly Reported or Calculated | J1: Verification Notes
A2: =Wheat_Yield_Data!A2 -> Attock | B2: =Wheat_Yield_Data!B2 -> 2010-11 | C2: =Wheat_Yield_Data!C2 -> 155800 | D2: =Wheat_Yield_Data!D2 -> 252650 | E2: =Wheat_Yield_Data!E2 -> 1621 | F2: Crop Reporting Service, Agriculture Dept Punjab - Rabi Crops Estimates 2011-12 (Rabi Book All estimates 2011-12), Final Estimate of Wheat Crop - value from prior-year column | G2: https://agripunjab.punjab.gov.pk/system/files/Rabi%20Book%20All%20estimates%202011-12_0.pdf | H2: Area p.3 (Area in '000' Hectares); Production p.4 (Production '000' Tonnes); Yield p.6 (Yield in Kgs/Hectares) | I2: Directly reported | J2: Value taken from the prior-year column of the Rabi Crops Estimates 2011-12 report. Published yield 1621 kg/ha vs production x 1000 / area = 1621.6 (difference -0.6, rounding).
A3: =Wheat_Yield_Data!A3 -> Attock | B3: =Wheat_Yield_Data!B3 -> 2011-12 | C3: =Wheat_Yield_Data!C3 -> 155390 | D3: =Wheat_Yield_Data!D3 -> 167110 | E3: =Wheat_Yield_Data!E3 -> 1075 | F3: Crop Reporting Service, Agriculture Dept Punjab - Rabi Crops Estimates 2011-12 (Rabi Book All estimates 2011-12), Final Estimate of Wheat Crop | G3: https://agripunjab.punjab.gov.pk/system/files/Rabi%20Book%20All%20estimates%202011-12_0.pdf | H3: Area p.3 (Area in '000' Hectares); Production p.4 (Production '000' Tonnes); Yield p.6 (Yield in Kgs/Hectares) | I3: Directly reported | J3: Published yield 1075 kg/ha vs production x 1000 / area = 1075.4 (difference -0.4, rounding).
A4: =Wheat_Yield_Data!A4 -> Attock | B4: =Wheat_Yield_Data!B4 -> 2012-13 | C4: =Wheat_Yield_Data!C4 -> 155800 | D4: =Wheat_Yield_Data!D4 -> 164470 | E4: =Wheat_Yield_Data!E4 -> 1056 | F4: Crop Reporting Service, Agriculture Dept Punjab - Rabi Crop Estimates Data Book 2013-14 (Final Rabi Estimates 2013-14), Final Estimate of Wheat Crop - value from prior-year column | G4: https://agripunjab.punjab.gov.pk/system/files/Final%20Rabi%20Estimates%202013-14.pdf | H4: Area p.3 (Area in '000' Hectares); Production p.4 (Production '000' Tonnes); Yield p.6 (Yield in Kgs/Hectares) | I4: Directly reported | J4: Value taken from the prior-year column of the Rabi Crop Estimates Data Book 2013-14 report. Published yield 1056 kg/ha vs production x 1000 / area = 1055.6 (difference 0.4, rounding). Cross-check vs AMIS Punjab - District Wise Data of Wheat 2012-14 <http://www.amis.pk/Agristatistics/DistrictWise/2012-2014/Wheat.html>: area 155,800 ha, production 164,500 t (area diff +0 ha, production diff +30 t).
A5: =Wheat_Yield_Data!A5 -> Attock | B5: =Wheat_Yield_Data!B5 -> 2013-14 | C5: =Wheat_Yield_Data!C5 -> 159040 | D5: =Wheat_Yield_Data!D5 -> 218330 | E5: =Wheat_Yield_Data!E5 -> 1372 | F5: Crop Reporting Service, Agriculture Dept Punjab - Rabi Crop Estimates Data Book 2013-14 (Final Rabi Estimates 2013-14), Final Estimate of Wheat Crop | G5: https://agripunjab.punjab.gov.pk/system/files/Final%20Rabi%20Estimates%202013-14.pdf | H5: Area p.3 (Area in '000' Hectares); Production p.4 (Production '000' Tonnes); Yield p.6 (Yield in Kgs/Hectares) | I5: Directly reported | J5: Published yield 1372 kg/ha vs production x 1000 / area = 1372.8 (difference -0.8, rounding). Cross-check vs AMIS Punjab - District Wise Data of Wheat 2012-14 <http://www.amis.pk/Agristatistics/DistrictWise/2012-2014/Wheat.html>: area 159,100 ha, production 218,300 t (area diff +60 ha, production diff -30 t).
A6: =Wheat_Yield_Data!A6 -> Attock | B6: =Wheat_Yield_Data!B6 -> 2014-15 | C6: =Wheat_Yield_Data!C6 -> 173610 | D6: =Wheat_Yield_Data!D6 -> 300940 | E6: =Wheat_Yield_Data!E6 -> 1733 | F6: Crop Reporting Service, Agriculture Dept Punjab - Rabi Crops Estimates Data Book 2015-16 (RABI BOOK 2015-16), Final Estimate of Wheat Crop - value from prior-year column | G6: https://agripunjab.punjab.gov.pk/system/files/RABI%20BOOK%202015-16_0.pdf | H6: Area p.3 (Area in '000' Hectares); Production p.4 (Production '000' Tonnes); Yield p.6 (Yield in Kgs/Hectares) | I6: Directly reported | J6: Value taken from the prior-year column of the Rabi Book 2015-16 report. Published yield 1733 kg/ha vs production x 1000 / area = 1733.4 (difference -0.4, rounding).
A7: =Wheat_Yield_Data!A7 -> Attock | B7: =Wheat_Yield_Data!B7 -> 2015-16 | C7: =Wheat_Yield_Data!C7 -> 187770 | D7: =Wheat_Yield_Data!D7 -> 335230 | E7: =Wheat_Yield_Data!E7 -> 1785.3225 | F7: Crop Reporting Service, Agriculture Dept Punjab - Rabi Crops Estimates Data Book 2015-16 (RABI BOOK 2015-16), Final Estimate of Wheat Crop | G7: https://agripunjab.punjab.gov.pk/system/files/RABI%20BOOK%202015-16_0.pdf | H7: Area p.3 (Area in '000' Hectares); Production p.4 (Production '000' Tonnes); Yield p.6 (Yield in Kgs/Hectares) | I7: Calculated | J7: The source prints a total yield of 1802 kg/ha, but the same row's printed area and production give 1785.3 kg/ha (difference 16.7). The row's own irrigated and un-irrigated yields agree with production/area, and the district sums match the printed provincial totals, so the printed total-yield cell is the inconsistent one. Yield is therefore calculated = production (t) x 1000 / area (ha); the printed value is kept here for reference.
A8: =Wheat_Yield_Data!A8 -> Attock | B8: =Wheat_Yield_Data!B8 -> 2016-17 | C8: =Wheat_Yield_Data!C8 -> 151350 | D8: =Wheat_Yield_Data!D8 -> 205030 | E8: =Wheat_Yield_Data!E8 -> 1355 | F8: Crop Reporting Service, Agriculture Dept Punjab - Final Rabi Estimates 2017-18, Final Estimate of Wheat Crop in the Punjab for the year 2017-2018 - value from prior-year column | G8: https://agripunjab.punjab.gov.pk/system/files/Final%20%20Rabi%20Estimates%202017-18.pdf | H8: Area wheat 'AREA IN '000' HECTARES' table; Production wheat 'PRODUCTION '000' TONNES' table; Yield wheat 'YIELD IN KGS / HECTARES' table (page numbers not printed in extracted text) | I8: Directly reported | J8: Value taken from the prior-year column of the Final Rabi Estimates 2017-18 report. Published yield 1355 kg/ha vs production x 1000 / area = 1354.7 (difference 0.3, rounding).
A9: =Wheat_Yield_Data!A9 -> Attock | B9: =Wheat_Yield_Data!B9 -> 2017-18 | C9: =Wheat_Yield_Data!C9 -> 151350 | D9: =Wheat_Yield_Data!D9 -> 223130 | E9: =Wheat_Yield_Data!E9 -> 1474 | F9: Crop Reporting Service, Agriculture Dept Punjab - Final Rabi Estimates 2017-18, Final Estimate of Wheat Crop in the Punjab for the year 2017-2018 | G9: https://agripunjab.punjab.gov.pk/system/files/Final%20%20Rabi%20Estimates%202017-18.pdf | H9: Area wheat 'AREA IN '000' HECTARES' table; Production wheat 'PRODUCTION '000' TONNES' table; Yield wheat 'YIELD IN KGS / HECTARES' table (page numbers not printed in extracted text) | I9: Directly reported | J9: Published yield 1474 kg/ha vs production x 1000 / area = 1474.3 (difference -0.3, rounding).
A10: =Wheat_Yield_Data!A10 -> Attock | B10: =Wheat_Yield_Data!B10 -> 2018-19 | C10: =Wheat_Yield_Data!C10 -> 151350 | D10: =Wheat_Yield_Data!D10 -> 286930 | E10: =Wheat_Yield_Data!E10 -> 1895 | F10: Crop Reporting Service, Agriculture Dept Punjab - Final Rabi Estimates 2018-19, Final Estimate of Wheat Crop in the Punjab for the year 2018-2019 | G10: https://agripunjab.punjab.gov.pk/system/files/Final%20Rabi%20Estimates%202018-19.pdf | H10: Area wheat 'AREA IN '000' HECTARES' table; Production wheat 'PRODUCTION '000' TONNES' table; Yield wheat 'YIELD IN KGS / HECTARES' table (page numbers not printed in extracted text) | I10: Directly reported | J10: Published yield 1895 kg/ha vs production x 1000 / area = 1895.8 (difference -0.8, rounding).
A11: =Wheat_Yield_Data!A11 -> Attock | B11: =Wheat_Yield_Data!B11 -> 2020-21 | C11: =Wheat_Yield_Data!C11 -> 203150 | D11: =Wheat_Yield_Data!D11 -> 359000 | E11: =Wheat_Yield_Data!E11 -> 1767 | F11: Crop Reporting Service, Agriculture Dept Punjab - Rabi Crops Estimates 2021-22 (Final Rabi Estimates 2021-22), Final Estimate of Wheat Crop - value from prior-year column | G11: https://agripunjab.punjab.gov.pk/system/files/Final%20Rabi%20Estimates%202021-22.pdf | H11: Area p.2 (Area in '000' Hectares); Production p.3 (Production '000' Tonnes); Yield p.5 (Yield in Kgs/Hectares) | I11: Directly reported | J11: Value taken from the prior-year column of the Rabi Crops Estimates 2021-22 report. Source prints the 2020-21 area total as 23.15; its printed components are 3.24 (irrigated) + 199.91 (un-irrigated) = 203.15 ('000 ha). 203.15 is consistent with the printed 502 ('000 acres), production 359.00 and yield 1767. Corrected value used. Published yield 1767 kg/ha vs production x 1000 / area = 1767.2 (difference -0.2, rounding).
A12: =Wheat_Yield_Data!A12 -> Attock | B12: =Wheat_Yield_Data!B12 -> 2021-22 | C12: =Wheat_Yield_Data!C12 -> 182920 | D12: =Wheat_Yield_Data!D12 -> 310340 | E12: =Wheat_Yield_Data!E12 -> 1697 | F12: Crop Reporting Service, Agriculture Dept Punjab - Rabi Crops Estimates 2021-22 (Final Rabi Estimates 2021-22), Final Estimate of Wheat Crop | G12: https://agripunjab.punjab.gov.pk/system/files/Final%20Rabi%20Estimates%202021-22.pdf | H12: Area p.2 (Area in '000' Hectares); Production p.3 (Production '000' Tonnes); Yield p.5 (Yield in Kgs/Hectares) | I12: Directly reported | J12: Published yield 1697 kg/ha vs production x 1000 / area = 1696.6 (difference 0.4, rounding).
A13: =Wheat_Yield_Data!A13 -> Attock | B13: =Wheat_Yield_Data!B13 -> 2022-23 | C13: =Wheat_Yield_Data!C13 -> 190200 | D13: =Wheat_Yield_Data!D13 -> 348200 | E13: =Wheat_Yield_Data!E13 -> 1831 | F13: Crop Reporting Service, Agriculture Dept Punjab - Final Rabi Estimates 2022-23, Final Estimate of Wheat Crop, Punjab 2022-23 | G13: https://agripunjab.punjab.gov.pk/system/files/Final%20Rabi%20Estimates%202022-23.pdf | H13: Area p.4 (Area in '000 hect); Production p.2 (Production in '000 tons); Yield p.5 (Avg. Yield Kg/Hect) | I13: Directly reported | J13: Published yield 1831 kg/ha vs production x 1000 / area = 1830.7 (difference 0.3, rounding).
... A437: =Wheat_Yield_Data!A437 -> Wazirabad | B437: =Wheat_Yield_Data!B437 -> 2022-23 | C437: =Wheat_Yield_Data!C437 -> 73700 | D437: =Wheat_Yield_Data!D437 -> 235000 | E437: =Wheat_Yield_Data!E437 -> 3191 | F437: Crop Reporting Service, Agriculture Dept Punjab - Final Rabi Estimates 2022-23, Final Estimate of Wheat Crop, Punjab 2022-23 | G437: https://agripunjab.punjab.gov.pk/system/files/Final%20Rabi%20Estimates%202022-23.pdf | H437: Area p.4 (Area in '000 hect); Production p.2 (Production in '000 tons); Yield p.5 (Avg. Yield Kg/Hect) | I437: Directly reported | J437: Published yield 3191 kg/ha vs production x 1000 / area = 3188.6 (difference 2.4, rounding).

Sheet Missing_Unverified
A1: District | B1: Season | C1: Reason | D1: Search Attempted | E1: Possible Source
A2: Attock | B2: 2019-20 | C2: No value entered - season not yet retrieved from an official report (nothing estimated or interpolated) | D2: CRS Final Rabi Estimates 2020-21 book (prior-year column) is on agripunjab.gov.pk, which blocks automated access (robots.txt); no 2019-20 book found on the accessible agripunjab.punjab.gov.pk host; AMIS 2019-20 PDF not opened | E2: https://agripunjab.gov.pk/system/files/Final%20Rabi%20Estimates%202020-21.pdf ; AMIS 'District Wise Area Production of Punjab 2019-20.pdf'
A3: Bahawalnagar | B3: 2019-20 | C3: No value entered - season not yet retrieved from an official report (nothing estimated or interpolated) | D3: CRS Final Rabi Estimates 2020-21 book (prior-year column) is on agripunjab.gov.pk, which blocks automated access (robots.txt); no 2019-20 book found on the accessible agripunjab.punjab.gov.pk host; AMIS 2019-20 PDF not opened | E3: https://agripunjab.gov.pk/system/files/Final%20Rabi%20Estimates%202020-21.pdf ; AMIS 'District Wise Area Production of Punjab 2019-20.pdf'
A4: Bahawalpur | B4: 2019-20 | C4: No value entered - season not yet retrieved from an official report (nothing estimated or interpolated) | D4: CRS Final Rabi Estimates 2020-21 book (prior-year column) is on agripunjab.gov.pk, which blocks automated access (robots.txt); no 2019-20 book found on the accessible agripunjab.punjab.gov.pk host; AMIS 2019-20 PDF not opened | E4: https://agripunjab.gov.pk/system/files/Final%20Rabi%20Estimates%202020-21.pdf ; AMIS 'District Wise Area Production of Punjab 2019-20.pdf'
A5: Bhakkar | B5: 2019-20 | C5: No value entered - season not yet retrieved from an official report (nothing estimated or interpolated) | D5: CRS Final Rabi Estimates 2020-21 book (prior-year column) is on agripunjab.gov.pk, which blocks automated access (robots.txt); no 2019-20 book found on the accessible agripunjab.punjab.gov.pk host; AMIS 2019-20 PDF not opened | E5: https://agripunjab.gov.pk/system/files/Final%20Rabi%20Estimates%202020-21.pdf ; AMIS 'District Wise Area Production of Punjab 2019-20.pdf'
A6: Chakwal | B6: 2019-20 | C6: No value entered - season not yet retrieved from an official report (nothing estimated or interpolated) | D6: CRS Final Rabi Estimates 2020-21 book (prior-year column) is on agripunjab.gov.pk, which blocks automated access (robots.txt); no 2019-20 book found on the accessible agripunjab.punjab.gov.pk host; AMIS 2019-20 PDF not opened | E6: https://agripunjab.gov.pk/system/files/Final%20Rabi%20Estimates%202020-21.pdf ; AMIS 'District Wise Area Production of Punjab 2019-20.pdf'
A7: Chiniot | B7: 2019-20 | C7: No value entered - season not yet retrieved from an official report (nothing estimated or interpolated) | D7: CRS Final Rabi Estimates 2020-21 book (prior-year column) is on agripunjab.gov.pk, which blocks automated access (robots.txt); no 2019-20 book found on the accessible agripunjab.punjab.gov.pk host; AMIS 2019-20 PDF not opened | E7: https://agripunjab.gov.pk/system/files/Final%20Rabi%20Estimates%202020-21.pdf ; AMIS 'District Wise Area Production of Punjab 2019-20.pdf'
A8: Dera Ghazi Khan | B8: 2019-20 | C8: No value entered - season not yet retrieved from an official report (nothing estimated or interpolated) | D8: CRS Final Rabi Estimates 2020-21 book (prior-year column) is on agripunjab.gov.pk, which blocks automated access (robots.txt); no 2019-20 book found on the accessible agripunjab.punjab.gov.pk host; AMIS 2019-20 PDF not opened | E8: https://agripunjab.gov.pk/system/files/Final%20Rabi%20Estimates%202020-21.pdf ; AMIS 'District Wise Area Production of Punjab 2019-20.pdf'
A9: Faisalabad | B9: 2019-20 | C9: No value entered - season not yet retrieved from an official report (nothing estimated or interpolated) | D9: CRS Final Rabi Estimates 2020-21 book (prior-year column) is on agripunjab.gov.pk, which blocks automated access (robots.txt); no 2019-20 book found on the accessible agripunjab.punjab.gov.pk host; AMIS 2019-20 PDF not opened | E9: https://agripunjab.gov.pk/system/files/Final%20Rabi%20Estimates%202020-21.pdf ; AMIS 'District Wise Area Production of Punjab 2019-20.pdf'
A10: Gujranwala | B10: 2019-20 | C10: No value entered - season not yet retrieved from an official report (nothing estimated or interpolated) | D10: CRS Final Rabi Estimates 2020-21 book (prior-year column) is on agripunjab.gov.pk, which blocks automated access (robots.txt); no 2019-20 book found on the accessible agripunjab.punjab.gov.pk host; AMIS 2019-20 PDF not opened | E10: https://agripunjab.gov.pk/system/files/Final%20Rabi%20Estimates%202020-21.pdf ; AMIS 'District Wise Area Production of Punjab 2019-20.pdf'
A11: Gujrat | B11: 2019-20 | C11: No value entered - season not yet retrieved from an official report (nothing estimated or interpolated) | D11: CRS Final Rabi Estimates 2020-21 book (prior-year column) is on agripunjab.gov.pk, which blocks automated access (robots.txt); no 2019-20 book found on the accessible agripunjab.punjab.gov.pk host; AMIS 2019-20 PDF not opened | E11: https://agripunjab.gov.pk/system/files/Final%20Rabi%20Estimates%202020-21.pdf ; AMIS 'District Wise Area Production of Punjab 2019-20.pdf'
A12: Hafizabad | B12: 2019-20 | C12: No value entered - season not yet retrieved from an official report (nothing estimated or interpolated) | D12: CRS Final Rabi Estimates 2020-21 book (prior-year column) is on agripunjab.gov.pk, which blocks automated access (robots.txt); no 2019-20 book found on the accessible agripunjab.punjab.gov.pk host; AMIS 2019-20 PDF not opened | E12: https://agripunjab.gov.pk/system/files/Final%20Rabi%20Estimates%202020-21.pdf ; AMIS 'District Wise Area Production of Punjab 2019-20.pdf'
... A77: Wazirabad | B77: 2023-24 | C77: No value entered - season not yet retrieved from an official report (nothing estimated or interpolated) | D77: CRS 'Rabi Crops Estimate 2023-24' page (lists Wheat) blocked by robots.txt; AMIS 'District Wise Crop data 2023-24.pdf' opened = Kharif book with no wheat | E77: https://crs-agripunjab.punjab.gov.pk/node/310 (Wheat 2023-24); AMIS 'Kharif Rabi Estimates in Punjab 2024-25.pdf' (prior-year column)

Sheet Summary
A1: Punjab district-level wheat dataset - Summary
A3: Total number of verified rows | B3: =COUNTA(Wheat_Yield_Data!A2:A437) -> 436
A4: Number of districts | B4: =COUNTA(District_Name_Map!B2:B41) -> 40
A5: Number of seasons | B5: =SUMPRODUCT(1/COUNTIF(Wheat_Yield_Data!B2:B437,Wheat_Yield_Data!B2:B437)) -> 12
A6: Earliest season | B6: 2010-11
A7: Latest season | B7: 2022-23
A8: Number of directly reported yields | B8: =COUNTIF(Wheat_Yield_Data!H2:H437,"*directly reported*") -> 417
A9: Number of calculated yields | B9: =COUNTIF(Wheat_Yield_Data!H2:H437,"*calculated*") -> 19
A10: Number of missing district-season observations | B10: =COUNTA(Missing_Unverified!A2:A77) -> 76
A11: Districts covered | B11: Attock, Bahawalnagar, Bahawalpur, Bhakkar, Chakwal, Chiniot, Dera Ghazi Khan, Faisalabad, Gujranwala, Gujrat, Hafizabad, Jhang, Jhelum, Kasur, Khanewal, Khushab, Kot Addu, Lahore, Layyah, Lodhran, Mandi Bahauddin, Mianwali, Multan, Murree, Muzaffargarh, Nankana Sahib, Narowal, Okara, Pakpattan, Rahim Yar Khan, Rajanpur, Rawalpindi, Sahiwal, Sargodha, Sheikhupura, Sialkot, Talagang, Toba Tek Singh, Vehari, Wazirabad
A12: Seasons covered | B12: 2010-11, 2011-12, 2012-13, 2013-14, 2014-15, 2015-16, 2016-17, 2017-18, 2018-19, 2020-21, 2021-22, 2022-23
A13: Seasons NOT covered (see Missing_Unverified) | B13: 2019-20, 2023-24
A15: Units, method and limitations
A16: Units | B16: Area in hectares and production in metric tonnes. Sources publish '000 hectares and '000 tonnes; values were multiplied by 1,000 (unit conversion only, no rounding change).
A17: Yield | B17: CRS tables publish yield in kg/ha (used as-is, 'directly reported'). Where the printed total yield contradicts the same row's area and production, yield is the formula = production x 1000 / area (live Excel formula in column E, status says 'calculated'). AMIS.pk (2012-14) is used only as a cross-check, listed in Source_Verification notes.
A18: Precision | B18: The CRS 2022-23 report prints area and production to 0.1 ('000) (all earlier reports print 2 decimals), so 2022-23 values are rounded to the nearest 100 ha / 100 t. Its published yields are used as printed.
A19: Seasons not covered | B19: 2019-20 (its only located source is the CRS 2020-21 book on agripunjab.gov.pk, which blocks automated access) and 2023-24 (CRS page blocks automated access) are not in the workbook. Nothing was estimated or interpolated for them.
A20: Meaning of 'Verified' | B20: Each value was read from the official PDF/HTML table named in Source and Source_Verification. For CRS rows the published yield was checked against production x 1000 / area (tolerance 2 kg/ha) and the district values were summed and compared with the printed provincial total. Rows were not independently re-keyed by a second person.
A21: Prior-year columns | B21: A CRS report shows the previous season next to the current one. Where the own-season report has not yet been read, the prior-year column is used and labelled as such. Where both exist, the own-season report is primary and the other is listed as a cross-check in Source_Verification (never a second row).
A22: Source typos corrected | B22: Three 2020-21 area cells in the CRS 2021-22 report are printed wrongly (Attock 23.15, Sargodha 59.89, R.Y. Khan 296.93 '000 ha). The correct figure is derivable from the printed row components and matches the printed acres, production and yield. Rows are flagged in Verification Status and explained in Source_Verification.
A23: Yield conflicts in source | B23: In some CRS tables the printed TOTAL yield of districts that have both irrigated and un-irrigated wheat does not equal that row's printed production / area (e.g. Attock 2015-16 prints 1802 but production/area = 1785). For those rows the yield is calculated from the printed area and production (status says so) and the printed value is kept in Source_Verification notes. Where the two agree (within 2 kg/ha) the printed CRS yield is used as 'directly reported'.
A24: Islamabad | B24: CRS tables list Islamabad (Islamabad Capital Territory) under Rawalpindi Division. It is not a Punjab district and is excluded from the dataset (it is included only when reconciling district sums with printed provincial totals).
A25: Sheikhupura | B25: Sheikhupura values are for Sheikhupura District. Nankana Sahib, separated from Sheikhupura in 2005, is reported separately in every source used.
A26: District names | B26: Wheat_Yield_Data uses the name as printed in the source; District_Name_Map gives the standardised name to use for grouping/joins.
A27: New districts | B27: Kot Addu, Murree, Talagang and Wazirabad appear in CRS tables from about 2022-23/2023-24. They have no earlier seasons and are not in this workbook yet.

Sheet District_Name_Map
A1: Name as printed in source(s) | B1: Standardised district name | C1: Note
A2: Attock | B2: Attock
A3: Bahawalnagar | B3: Bahawalnagar
A4: Bahawalpur | B4: Bahawalpur
A5: Bhakkar | B5: Bhakkar
A6: Chakwal | B6: Chakwal
A7: Chiniot | B7: Chiniot
A8: D.G. Khan | B8: Dera Ghazi Khan | C8: Printed as 'D.G. Khan'.
A9: Faisalabad | B9: Faisalabad
A10: Gujranwala | B10: Gujranwala
A11: Gujrat | B11: Gujrat
A12: Hafizabad | B12: Hafizabad
A13: Jhang | B13: Jhang
A14: Jhelum | B14: Jhelum
A15: Kasur | B15: Kasur
A16: Khanewal | B16: Khanewal
A17: Khushab | B17: Khushab
A18: Kot Addu | B18: Kot Addu
A19: Lahore | B19: Lahore
A20: Layyah | B20: Layyah
A21: Lodhran | B21: Lodhran
A22: M.B. Din | M.B.Din | B22: Mandi Bahauddin | C22: Printed as 'M.B. Din' / 'M.B.Din'.
A23: Mianwali | B23: Mianwali
A24: Multan | B24: Multan
A25: Muree | B25: Murree
A26: M. Garh | Muzaffargarh | Muzzafargargh | B26: Muzaffargarh | C26: Printed as 'Muzaffargarh' (CRS) and 'M. Garh' (AMIS).
A27: Nankana Sahib | B27: Nankana Sahib | C27: Carved out of Sheikhupura District (2005); reported separately in every source used - Sheikhupura values are Sheikhupura District only.
A28: Narowal | B28: Narowal
A29: Okara | B29: Okara
A30: Pakpattan | B30: Pakpattan
A31: R.Y. Khan | Rahim Yar Khan | Rahimyar Khan | B31: Rahim Yar Khan | C31: Printed as 'Rahim Yar Khan', 'R.Y. Khan', 'Rahimyar Khan'.
A32: Rajan Pur | Rajanpur | B32: Rajanpur | C32: Printed as 'Rajan Pur' (CRS) and 'Rajanpur' (AMIS).
A33: Rawalpindi | B33: Rawalpindi
A34: Sahiwal | B34: Sahiwal
A35: Sargodha | B35: Sargodha
A36: Sheikhupura | B36: Sheikhupura
A37: Sialkot | B37: Sialkot
A38: Talagang | B38: Talagang
A39: T.T. Singh | Toba Tek Singh | B39: Toba Tek Singh | C39: Printed as 'T.T. Singh' (CRS) and 'Toba Tek Singh' (AMIS).
A40: Vehari | B40: Vehari
...
